<?xml version="1.0" ?>
<!-- =================================================================================== -->
<!-- |    This document was autogenerated by xacro from kr16_2.xacro                   | -->
<!-- |    EDITING THIS FILE BY HAND IS NOT RECOMMENDED                                 | -->
<!-- =================================================================================== -->
<!--Generates a urdf from the macro in kr16_2_macro.xacro -->
<robot name="kuka_kr20_r1810_2" xmlns:xacro="http://wiki.ros.org/xacro">
  <!-- LINKS -->
  <!-- base link -->
  <link name="base_link">
    <inertial>
      <origin rpy="0 0 0" xyz="0 0 0"/>
      <mass value="2"/>
      <inertia ixx="0.01" ixy="0" ixz="0" iyy="0.01" iyz="0" izz="0.01"/>
    </inertial>
    <visual>
      <origin rpy="0 0 0" xyz="0 0 0"/>
      <geometry>
        <mesh filename="package://kuka_kr20_support/meshes/kuka_kr20_r1810_2/visual/base_link.stl" scale="0.001 0.001 0.001"/>
      </geometry>
      <material
        name="">
        <color
          rgba="0.1 0.1 0.1 1" />
      </material>
    </visual>
    <collision>
      <origin rpy="0 0 0" xyz="0 0 0"/>
      <geometry>
        <mesh filename="package://kuka_kr20_support/meshes/kuka_kr20_r1810_2/collision/base_link.stl" scale="0.001 0.001 0.001"/>
      </geometry>
    </collision>
  </link>
  <!-- link 1 (A1) -->
  <link name="link_1">
    <inertial>
      <origin rpy="0 0 0" xyz="0 0 0"/>
      <mass value="2"/>
      <inertia ixx="0.01" ixy="0" ixz="0" iyy="0.01" iyz="0" izz="0.01"/>
    </inertial>
    <visual>
      <origin rpy="0 0 0" xyz="0 0 0"/>
      <geometry>
        <mesh filename="package://kuka_kr20_support/meshes/kuka_kr20_r1810_2/visual/link_1.stl" scale="0.001 0.001 0.001"/>
      </geometry>
      <material
        name="">
        <color
          rgba="1.0 0.487 0 1.0" />
      </material>
    </visual>
    <collision>
      <origin rpy="0 0 0" xyz="0 0 0"/>
      <geometry>
        <mesh filename="package://kuka_kr20_support/meshes/kuka_kr20_r1810_2/collision/link_1.stl" scale="0.001 0.001 0.001"/>
      </geometry>
    </collision>
  </link>
  <!-- link 2 -->
  <link name="link_2">
    <inertial>
      <origin rpy="0 0 0" xyz="0 0 0"/>
      <mass value="2"/>
      <inertia ixx="0.01" ixy="0" ixz="0" iyy="0.01" iyz="0" izz="0.01"/>
    </inertial>
    <visual>
      <origin rpy="0 0 0" xyz="0 0 0"/>
      <geometry>
        <mesh filename="package://kuka_kr20_support/meshes/kuka_kr20_r1810_2/visual/link_2.stl" scale="0.001 0.001 0.001"/>
      </geometry>
      <material
        name="">
        <color
          rgba="1.0 0.487 0 1.0" />
      </material>
    </visual>
    <collision>
      <origin rpy="0 0 0" xyz="0 0 0"/>
      <geometry>
        <mesh filename="package://kuka_kr20_support/meshes/kuka_kr20_r1810_2/collision/link_2.stl" scale="0.001 0.001 0.001"/>
      </geometry>
    </collision>
  </link>
  <!-- link 3 -->
  <link name="link_3">
    <inertial>
      <origin rpy="0 0 0" xyz="0 0 0"/>
      <mass value="2"/>
      <inertia ixx="0.01" ixy="0" ixz="0" iyy="0.01" iyz="0" izz="0.01"/>
    </inertial>
    <visual>
      <origin rpy="0 0 0" xyz="0 0 0"/>
      <geometry>
        <mesh filename="package://kuka_kr20_support/meshes/kuka_kr20_r1810_2/visual/link_3.stl" scale="0.001 0.001 0.001"/>
      </geometry>
      <material
        name="">
        <color
          rgba="1.0 0.487 0 1.0" />
      </material>
    </visual>
    <collision>
      <origin rpy="0 0 0" xyz="0 0 0"/>
      <geometry>
        <mesh filename="package://kuka_kr20_support/meshes/kuka_kr20_r1810_2/collision/link_3.stl" scale="0.001 0.001 0.001"/>
      </geometry>
    </collision>
  </link>
  <!-- link 4 -->
  <link name="link_4">
    <inertial>
      <origin rpy="0 0 0" xyz="0 0 0"/>
      <mass value="2"/>
      <inertia ixx="0.01" ixy="0" ixz="0" iyy="0.01" iyz="0" izz="0.01"/>
    </inertial>
    <visual>
      <origin rpy="0 0 0" xyz="0 0 0"/>
      <geometry>
        <mesh filename="package://kuka_kr20_support/meshes/kuka_kr20_r1810_2/visual/link_4.stl" scale="0.001 0.001 0.001"/>
      </geometry>
      <material
        name="">
        <color
          rgba="1.0 0.487 0 1.0" />
      </material>
    </visual>
    <collision>
      <origin rpy="0 0 0" xyz="0 0 0"/>
      <geometry>
        <mesh filename="package://kuka_kr20_support/meshes/kuka_kr20_r1810_2/collision/link_4.stl" scale="0.001 0.001 0.001"/>
      </geometry>
    </collision>
  </link>
  <!-- link 5 -->
  <link name="link_5">
    <inertial>
      <origin rpy="0 0 0" xyz="0 0 0"/>
      <mass value="2"/>
      <inertia ixx="0.01" ixy="0" ixz="0" iyy="0.01" iyz="0" izz="0.01"/>
    </inertial>
    <visual>
      <origin rpy="0 0 0" xyz="0 0 0"/>
      <geometry>
        <mesh filename="package://kuka_kr20_support/meshes/kuka_kr20_r1810_2/visual/link_5.stl" scale="0.001 0.001 0.001"/>
      </geometry>
      <material
        name="">
        <color
          rgba="1.0 0.487 0 1.0" />
      </material>
    </visual>
    <collision>
      <origin rpy="0 0 0" xyz="0 0 0"/>
      <geometry>
        <mesh filename="package://kuka_kr20_support/meshes/kuka_kr20_r1810_2/collision/link_5.stl" scale="0.001 0.001 0.001"/>
      </geometry>
    </collision>
  </link>
  <!-- link 6 -->
  <link name="link_6">
    <inertial>
      <origin rpy="0 0 0" xyz="0 0 0"/>
      <mass value="2"/>
      <inertia ixx="0.01" ixy="0" ixz="0" iyy="0.01" iyz="0" izz="0.01"/>
    </inertial>
    <visual>
      <origin rpy="0 0 0" xyz="0 0 0"/>
      <geometry>
        <mesh filename="package://kuka_kr20_support/meshes/kuka_kr20_r1810_2/visual/link_6.stl" scale="0.001 0.001 0.001"/>
      </geometry>
      <material
        name="">
        <color
          rgba="1.0 0.487 0 1.0" />
      </material>
    </visual>
    <collision>
      <origin rpy="0 0 0" xyz="0 0 0"/>
      <geometry>
        <mesh filename="package://kuka_kr20_support/meshes/kuka_kr20_r1810_2/collision/link_6.stl" scale="0.001 0.001 0.001"/>
      </geometry>
    </collision>
  </link>
  <!-- tool 0 -->
  <!-- This frame corresponds to the $FLANGE coordinate system in KUKA KRC controllers. -->
<!--   <link name="tool0"/> -->

  <link name="tool0">
    <visual>
      <origin xyz="0 0 0" rpy="-1.5708 -1.5708 0"/>
      <geometry>
        <mesh scale = "0.001 0.001 0.001" filename="package://kuka_kr20_support/meshes/kuka_kr20_r1810_2/visual/photoneo_l515_mount_v3.STL"/>
      </geometry>
      <material
        name="">
        <color
          rgba="0.1 0.75 0.75 0.9"/>
      </material>
    </visual>
  </link>  

  <link name="tcp">
    <visual>
      <origin xyz="0 0 0" rpy="0 3.1416 1.5708"/>
      <geometry>
        <mesh scale = "1.0 1.0 1.0" filename="package://kuka_kr20_support/meshes/kuka_kr20_r1810_2/visual/PhotoneoFrustum.STL"/>
      </geometry>
      <material
        name="">
        <color
          rgba="0.75 0.75 0.25 0.75"/>
      </material>
    </visual>
  </link>  

  <link name="p_frustum"/>

  <!-- END LINKS -->
  <!-- JOINTS -->
  <!-- joint 1 (A1) -->
  <joint name="joint_a1" type="revolute">
    <origin rpy="0 0 0" xyz="0 0 0.519"/>
    <parent link="base_link"/>
    <child link="link_1"/>
    <axis xyz="0 0 -1"/>
    <limit effort="0" lower="-3.22885911619" upper="3.22885911619" velocity="2.72271363311"/>
  </joint>
  <!-- joint 2 (A2) -->
  <joint name="joint_a2" type="revolute">
    <origin rpy="0 0 0" xyz="0.16 0 0"/>
    <parent link="link_1"/>
    <child link="link_2"/>
    <axis xyz="0 1 0"/>
    <limit effort="0" lower="-2.70526034059" upper="0.610865238198" velocity="2.72271363311"/>
  </joint>
  <!-- joint 3 (A3) -->
  <joint name="joint_a3" type="revolute">
    <origin rpy="0 0 0" xyz="0.78 0 0"/>
    <parent link="link_2"/>
    <child link="link_3"/>
    <axis xyz="0 1 0"/>
    <limit effort="0" lower="-2.26892802759" upper="2.68780704807" velocity="2.72271363311"/>
  </joint>
  <!-- joint 4 (A4) -->
  <joint name="joint_a4" type="revolute">
    <origin rpy="0 0 0" xyz="0 0 0.150"/>
    <parent link="link_3"/>
    <child link="link_4"/>
    <axis xyz="-1 0 0"/>
    <limit effort="0" lower="-6.10865238198" upper="6.10865238198" velocity="5.75958653158"/>
  </joint>
  <!-- joint 5 (A5) -->
  <joint name="joint_a5" type="revolute">
    <origin rpy="0 0 0" xyz="0.86 0 0"/>
    <parent link="link_4"/>
    <child link="link_5"/>
    <axis xyz="0 1 0"/>
    <limit effort="0" lower="-2.26892802759" upper="2.26892802759" velocity="5.75958653158"/>
  </joint>
  <!-- joint 6 (A6) -->
  <joint name="joint_a6" type="revolute">
    <origin rpy="0 0 0" xyz="0.153 0 0"/>
    <parent link="link_5"/>
    <child link="link_6"/>
    <axis xyz="-1 0 0"/>
    <limit effort="0" lower="-6.10865238198" upper="6.10865238198" velocity="10.7337748998"/>
  </joint>
  <!-- tool frame - fixed frame -->
  <joint name="joint_a6-tool0" type="fixed">
    <parent link="link_6"/>
    <child link="tool0"/>
    <origin rpy="0 1.57079632679 0" xyz="0 0 0"/>
  </joint>
  <!-- END JOINTS -->
  <!-- ROS base_link to KUKA $ROBROOT coordinate system transform -->
  <link name="base"/>
  <joint name="base_link-base" type="fixed">
    <origin rpy="0 0 0" xyz="0 0 0"/>
    <parent link="base_link"/>
    <child link="base"/>
  </joint>
<!-- TCP offset to the photoneo sensor -->
  <joint
    name="joint_tcp"
    type="fixed">
    <origin
      xyz="0 0 0.16"
      rpy="0 0 0" />
    <parent
      link="tool0" />
    <child
      link="tcp" />
  </joint> 
<!--   Offset to the photoneo optimal scanning distance --> 
  <joint
    name="p_frustum_joint"
    type="fixed">
    <origin
      xyz="0 0 0.442"
      rpy="0 0 0" />
    <parent
      link="tcp" />
    <child
      link="p_frustum" />
  </joint> 

</robot>

